<?xml version="1.0"?>
<robot name="truck" xmlns:xacro="http://ros.org/wiki/xacro">

    <xacro:property name="head_length"  value="2" />
    <xacro:property name="head_width"   value="1" />
    <xacro:property name="head_height"  value="1" />

    <xacro:property name="tail_length"  value="4" />
    <xacro:property name="tail_width"   value="1" />
    <xacro:property name="tail_height"  value="1" />

    <link name="head">
        <visual>
            <geometry>
                <box size="${head_length} ${head_width} ${head_height}" />
            </geometry>
        </visual>
    </link>

    <link name="tail">
        <visual>
            <geometry>
                <box size="${tail_length} ${tail_width} ${tail_height}" />
            </geometry>
            <origin xyz="-1.5 0 0"/>
        </visual>
    </link>

    <joint name="link" type="revolute">
        <parent link="head"/>
        <child link="tail"/>
        <axis xyz="0 0 1"/>
        <limit effort="1000.0" lower="-1.57" upper="1.57" velocity="10" />
        <origin xyz="-0.5 0 0"/>
    </joint>

</robot>
